Workbook

Sheet 📦 Raw Data
A1: 📦 EMPLOYEE SALES DATASET — Raw Data Source
A2: Use this sheet as the data source for all formula practice sheets
A4: TABLE A — Employee Master (Reference Range: A5:K30)
A5: Emp ID | B5: Employee Name | C5: Department | D5: Region | E5: Level | F5: Base Salary | G5: Sales Amount | H5: Quarter | I5: Year | J5: Status | K5: Bonus %
A6: E001 | B6: Amit Shah | C6: Sales | D6: North | E6: Senior | F6: 82000 | G6: 145000 | H6: Q1 | I6: 2024 | J6: Active | K6: =IF(E6="Senior",15%,IF(E6="Mid",10%,5%)) -> 0.15
A7: E002 | B7: Priya Patel | C7: Marketing | D7: West | E7: Junior | F7: 45000 | G7: 0 | H7: Q1 | I7: 2024 | J7: Active | K7: =IF(E7="Senior",15%,IF(E7="Mid",10%,5%)) -> 0.05
A8: E003 | B8: Ravi Kumar | C8: Sales | D8: South | E8: Mid | F8: 61000 | G8: 98000 | H8: Q2 | I8: 2024 | J8: Active | K8: =IF(E8="Senior",15%,IF(E8="Mid",10%,5%)) -> 0.1
A9: E004 | B9: Sneha Mehta | C9: IT | D9: East | E9: Senior | F9: 78000 | G9: 0 | H9: Q1 | I9: 2024 | J9: Active | K9: =IF(E9="Senior",15%,IF(E9="Mid",10%,5%)) -> 0.15 | M9: VLOOKup
A10: E005 | B10: Karan Joshi | C10: Sales | D10: North | E10: Senior | F10: 91000 | G10: 162000 | H10: Q2 | I10: 2024 | J10: Active | K10: =IF(E10="Senior",15%,IF(E10="Mid",10%,5%)) -> 0.15 | M10: Emp ID | N10: E027
A11: E006 | B11: Divya Sharma | C11: HR | D11: West | E11: Mid | F11: 52000 | G11: 0 | H11: Q3 | I11: 2024 | J11: Active | K11: =IF(E11="Senior",15%,IF(E11="Mid",10%,5%)) -> 0.1 | M11: emp name | N11: =IFERROR(_xlfn.XLOOKUP(N10,$A$6:$K$30,2,TRUE),"Not Found") -> Not Found
A12: E007 | B12: Ankit Gupta | C12: Sales | D12: East | E12: Junior | F12: 38000 | G12: 54000 | H12: Q3 | I12: 2024 | J12: Active | K12: =IF(E12="Senior",15%,IF(E12="Mid",10%,5%)) -> 0.05 | M12: dep | N12: =VLOOKUP(N10,$A$6:$K$30,3,TRUE) -> Sales
A13: E008 | B13: Neha Singh | C13: Finance | D13: South | E13: Senior | F13: 85000 | G13: 0 | H13: Q2 | I13: 2024 | J13: Active | K13: =IF(E13="Senior",15%,IF(E13="Mid",10%,5%)) -> 0.15 | M13: level | N13: =VLOOKUP(N10,$A$6:$K$30,5,TRUE) -> Junior
A14: E009 | B14: Vikram Rao | C14: Sales | D14: West | E14: Mid | F14: 67000 | G14: 112000 | H14: Q4 | I14: 2024 | J14: Active | K14: =IF(E14="Senior",15%,IF(E14="Mid",10%,5%)) -> 0.1 | M14: salary | N14: =VLOOKUP(N10,$A$6:$K$30,6,TRUE) -> 37000
A15: E010 | B15: Meera Nair | C15: Marketing | D15: North | E15: Senior | F15: 74000 | G15: 0 | H15: Q4 | I15: 2024 | J15: Active | K15: =IF(E15="Senior",15%,IF(E15="Mid",10%,5%)) -> 0.15
A16: E011 | B16: Sanjay Verma | C16: Sales | D16: South | E16: Junior | F16: 41000 | G16: 63000 | H16: Q1 | I16: 2024 | J16: Inactive | K16: =IF(E16="Senior",15%,IF(E16="Mid",10%,5%)) -> 0.05
A17: E012 | B17: Pooja Agarwal | C17: IT | D17: West | E17: Mid | F17: 59000 | G17: 0 | H17: Q2 | I17: 2024 | J17: Active | K17: =IF(E17="Senior",15%,IF(E17="Mid",10%,5%)) -> 0.1 | M17: SUMIF
A18: E013 | B18: Rajesh Pandey | C18: Sales | D18: East | E18: Senior | F18: 88000 | G18: 175000 | H18: Q3 | I18: 2024 | J18: Active | K18: =IF(E18="Senior",15%,IF(E18="Mid",10%,5%)) -> 0.15 | M18: Sales | N18: =SUMIF(C6:C30,M18,F6:F30) -> 856000
A19: E014 | B19: Asha Desai | C19: Finance | D19: North | E19: Junior | F19: 42000 | G19: 0 | H19: Q4 | I19: 2024 | J19: Active | K19: =IF(E19="Senior",15%,IF(E19="Mid",10%,5%)) -> 0.05
A20: E015 | B20: Nikhil Tiwari | C20: Sales | D20: West | E20: Mid | F20: 64000 | G20: 107000 | H20: Q1 | I20: 2025 | J20: Active | K20: =IF(E20="Senior",15%,IF(E20="Mid",10%,5%)) -> 0.1
A21: E016 | B21: Kavya Menon | C21: HR | D21: South | E21: Senior | F21: 71000 | G21: 0 | H21: Q2 | I21: 2025 | J21: Active | K21: =IF(E21="Senior",15%,IF(E21="Mid",10%,5%)) -> 0.15 | M21: SUMIFS
A22: E017 | B22: Arjun Kapoor | C22: Sales | D22: North | E22: Senior | F22: 93000 | G22: 158000 | H22: Q3 | I22: 2025 | J22: Active | K22: =IF(E22="Senior",15%,IF(E22="Mid",10%,5%)) -> 0.15 | N22: North | O22: South
A23: E018 | B23: Lakshmi Iyer | C23: Marketing | D23: East | E23: Mid | F23: 55000 | G23: 0 | H23: Q4 | I23: 2025 | J23: Active | K23: =IF(E23="Senior",15%,IF(E23="Mid",10%,5%)) -> 0.1 | M23: Sales | N23: =SUMIFS($F$6:$F$30,$C$6:$C$30,M23,$D$6:$D$30,N22) -> 303000 | O23: =SUMIFS($F$6:$F$30,$C$6:$C$30,M23,$D$6:$D$30,O22) -> 141000
A24: E019 | B24: Rohit Bose | C24: Sales | D24: South | E24: Junior | F24: 39000 | G24: 71000 | H24: Q1 | I24: 2025 | J24: Active | K24: =IF(E24="Senior",15%,IF(E24="Mid",10%,5%)) -> 0.05
A25: E020 | B25: Sunita Pillai | C25: IT | D25: West | E25: Senior | F25: 82000 | G25: 0 | H25: Q2 | I25: 2025 | J25: Active | K25: =IF(E25="Senior",15%,IF(E25="Mid",10%,5%)) -> 0.15
A26: E021 | B26: Deepak Yadav | C26: Sales | D26: East | E26: Mid | F26: 66000 | G26: 123000 | H26: Q3 | I26: 2025 | J26: Active | K26: =IF(E26="Senior",15%,IF(E26="Mid",10%,5%)) -> 0.1
A27: E022 | B27: Ananya Roy | C27: Finance | D27: North | E27: Mid | F27: 57000 | G27: 0 | H27: Q4 | I27: 2025 | J27: Active | K27: =IF(E27="Senior",15%,IF(E27="Mid",10%,5%)) -> 0.1
A28: E023 | B28: Pranav Mishra | C28: Sales | D28: West | E28: Senior | F28: 89000 | G28: 141000 | H28: Q1 | I28: 2025 | J28: Active | K28: =IF(E28="Senior",15%,IF(E28="Mid",10%,5%)) -> 0.15
A29: E024 | B29: Shruti Das | C29: Marketing | D29: South | E29: Junior | F29: 44000 | G29: 0 | H29: Q2 | I29: 2025 | J29: Inactive | K29: =IF(E29="Senior",15%,IF(E29="Mid",10%,5%)) -> 0.05
A30: E025 | B30: Gaurav Saxena | C30: Sales | D30: North | E30: Junior | F30: 37000 | G30: 58000 | H30: Q3 | I30: 2025 | J30: Active | K30: =IF(E30="Senior",15%,IF(E30="Mid",10%,5%)) -> 0.05
A33: TABLE B — Product Catalogue (Reference Range: A34:E44)
A34: Product ID | B34: Product Name | C34: Category | D34: Selling Price (₹) | E34: Cost Price (₹)
A35: P001 | B35: Laptop Pro | C35: Electronics | D35: 85000 | E35: 65000
A36: P002 | B36: Office Chair | C36: Furniture | D36: 12000 | E36: 7500
A37: P003 | B37: Standing Desk | C37: Furniture | D37: 25000 | E37: 18000
A38: P004 | B38: Noise Headphones | C38: Electronics | D38: 15000 | E38: 10000
A39: P005 | B39: Webcam HD | C39: Electronics | D39: 8500 | E39: 5500
A40: P006 | B40: Monitor 27" | C40: Electronics | D40: 35000 | E40: 26000
A41: P007 | B41: Keyboard Mech | C41: Electronics | D41: 6500 | E41: 4200
A42: P008 | B42: Ergonomic Mouse | C42: Electronics | D42: 4500 | E42: 2800
A43: P009 | B43: Filing Cabinet | C43: Furniture | D43: 18000 | E43: 13000
...

Sheet 🔍 XLOOKUP
A1: 🔍 XLOOKUP — Modern Lookup Formula
A3: 📖 What is XLOOKUP?
A4: Syntax: | C4: xlookup(lookup_value, lookup_array, return_array, [if_not_found], [match_mode], [search_mode])
A5: lookup_value: | C5: The value you are searching for
A6: lookup_array: | C6: The column/row to search IN
A7: return_array: | C7: The column/row to return data FROM
A8: [if_not_found]: | C8: What to show when nothing is found → wrap with IFERROR or use this argument
A9: Advantage over VLOOKUP: | C9: ✅ Can look left ✅ Returns whole range ✅ No column number needed ✅ Built-in error handling
A11: EXAMPLE 1 — Look up Employee Name by ID
A12: Emp ID to Find | B12: Employee Name | C12: Department | D12: Level | E12: Sales Amount | F12: Status
A13: E005 | B13: =IFERROR(_xlfn.XLOOKUP(A13,'📦 Raw Data'!A$6:A$30,'📦 Raw Data'!B$6:B$30),"❌ Not Found") -> Karan Joshi | C13: =IFERROR(_xlfn.XLOOKUP(A13,'📦 Raw Data'!A$6:A$30,'📦 Raw Data'!C$6:C$30),"❌ Not Found") -> Sales | D13: =IFERROR(_xlfn.XLOOKUP(A13,'📦 Raw Data'!A$6:A$30,'📦 Raw Data'!E$6:E$30),"❌ Not Found") -> Senior | E13: =IFERROR(_xlfn.XLOOKUP(A13,'📦 Raw Data'!A$6:A$30,'📦 Raw Data'!G$6:G$30),"❌ Not Found") -> 162000 | F13: =IFERROR(_xlfn.XLOOKUP(A13,'📦 Raw Data'!A$6:A$30,'📦 Raw Data'!J$6:J$30),"❌ Not Found") -> Active
A14: E013 | B14: =IFERROR(_xlfn.SINGLE(_xlfn.XLOOKUP(A14,'📦 Raw Data'!A$6:A$30,'📦 Raw Data'!B$6:B$30)),"❌ Not Found") -> Rajesh Pandey | C14: =IFERROR(_xlfn.XLOOKUP(A14,'📦 Raw Data'!A$6:A$30,'📦 Raw Data'!C$6:C$30),"❌ Not Found") -> Sales | D14: =IFERROR(_xlfn.XLOOKUP(A14,'📦 Raw Data'!A$6:A$30,'📦 Raw Data'!E$6:E$30),"❌ Not Found") -> Senior | E14: =IFERROR(_xlfn.XLOOKUP(A14,'📦 Raw Data'!A$6:A$30,'📦 Raw Data'!G$6:G$30),"❌ Not Found") -> 175000 | F14: =IFERROR(_xlfn.XLOOKUP(A14,'📦 Raw Data'!A$6:A$30,'📦 Raw Data'!J$6:J$30),"❌ Not Found") -> Active
A15: E017 | B15: =IFERROR(_xlfn.SINGLE(_xlfn.XLOOKUP(A15,'📦 Raw Data'!A$6:A$30,'📦 Raw Data'!B$6:B$30)),"❌ Not Found") -> Arjun Kapoor | C15: =IFERROR(_xlfn.XLOOKUP(A15,'📦 Raw Data'!A$6:A$30,'📦 Raw Data'!C$6:C$30),"❌ Not Found") -> Sales | D15: =IFERROR(_xlfn.XLOOKUP(A15,'📦 Raw Data'!A$6:A$30,'📦 Raw Data'!E$6:E$30),"❌ Not Found") -> Senior | E15: =IFERROR(_xlfn.XLOOKUP(A15,'📦 Raw Data'!A$6:A$30,'📦 Raw Data'!G$6:G$30),"❌ Not Found") -> 158000 | F15: =IFERROR(_xlfn.XLOOKUP(A15,'📦 Raw Data'!A$6:A$30,'📦 Raw Data'!J$6:J$30),"❌ Not Found") -> Active
A16: E001 | B16: =IFERROR(_xlfn.SINGLE(_xlfn.XLOOKUP(A16,'📦 Raw Data'!A$6:A$30,'📦 Raw Data'!B$6:B$30)),"❌ Not Found") -> Amit Shah | C16: =IFERROR(_xlfn.XLOOKUP(A16,'📦 Raw Data'!A$6:A$30,'📦 Raw Data'!C$6:C$30),"❌ Not Found") -> Sales | D16: =IFERROR(_xlfn.XLOOKUP(A16,'📦 Raw Data'!A$6:A$30,'📦 Raw Data'!E$6:E$30),"❌ Not Found") -> Senior | E16: =IFERROR(_xlfn.XLOOKUP(A16,'📦 Raw Data'!A$6:A$30,'📦 Raw Data'!G$6:G$30),"❌ Not Found") -> 145000 | F16: =IFERROR(_xlfn.XLOOKUP(A16,'📦 Raw Data'!A$6:A$30,'📦 Raw Data'!J$6:J$30),"❌ Not Found") -> Active
A17: E999 | B17: =IFERROR(_xlfn.SINGLE(_xlfn.XLOOKUP(A17,'📦 Raw Data'!A$6:A$30,'📦 Raw Data'!B$6:B$30)),"❌ Not Found") -> ❌ Not Found | C17: =IFERROR(_xlfn.XLOOKUP(A17,'📦 Raw Data'!A$6:A$30,'📦 Raw Data'!C$6:C$30),"❌ Not Found") -> ❌ Not Found | D17: =IFERROR(_xlfn.XLOOKUP(A17,'📦 Raw Data'!A$6:A$30,'📦 Raw Data'!E$6:E$30),"❌ Not Found") -> ❌ Not Found | E17: =IFERROR(_xlfn.XLOOKUP(A17,'📦 Raw Data'!A$6:A$30,'📦 Raw Data'!G$6:G$30),"❌ Not Found") -> ❌ Not Found | F17: =IFERROR(_xlfn.XLOOKUP(A17,'📦 Raw Data'!A$6:A$30,'📦 Raw Data'!J$6:J$30),"❌ Not Found") -> ❌ Not Found
A19: EXAMPLE 2 — Product Lookup (from Product Table B)
A20: Product ID | B20: Product Name | C20: Category | D20: Selling Price | E20: Cost Price | F20: Profit Margin
A21: P003 | B21: =IFERROR(_xlfn.XLOOKUP(A21,'📦 Raw Data'!A$35:A$44,'📦 Raw Data'!B$35:B$44),"❌ Not Found") -> Standing Desk | C21: =IFERROR(_xlfn.XLOOKUP(A21,'📦 Raw Data'!A$35:A$44,'📦 Raw Data'!C$35:C$44),"❌ Not Found") -> Furniture | D21: =IFERROR(_xlfn.XLOOKUP(A21,'📦 Raw Data'!A$35:A$44,'📦 Raw Data'!D$35:D$44),"❌ Not Found") -> 25000 | E21: =IFERROR(_xlfn.XLOOKUP(A21,'📦 Raw Data'!A$35:A$44,'📦 Raw Data'!E$35:E$44),"❌ Not Found") -> 18000 | F21: =IFERROR((D21-E21)/D21,"N/A") -> 0.28
A22: P006 | B22: =IFERROR(_xlfn.XLOOKUP(A22,'📦 Raw Data'!A$35:A$44,'📦 Raw Data'!B$35:B$44),"❌ Not Found") -> Monitor 27" | C22: =IFERROR(_xlfn.XLOOKUP(A22,'📦 Raw Data'!A$35:A$44,'📦 Raw Data'!C$35:C$44),"❌ Not Found") -> Electronics | D22: =IFERROR(_xlfn.XLOOKUP(A22,'📦 Raw Data'!A$35:A$44,'📦 Raw Data'!D$35:D$44),"❌ Not Found") -> 35000 | E22: =IFERROR(_xlfn.XLOOKUP(A22,'📦 Raw Data'!A$35:A$44,'📦 Raw Data'!E$35:E$44),"❌ Not Found") -> 26000 | F22: =IFERROR((D22-E22)/D22,"N/A") -> 0.25714286
A23: P010 | B23: =IFERROR(_xlfn.XLOOKUP(A23,'📦 Raw Data'!A$35:A$44,'📦 Raw Data'!B$35:B$44),"❌ Not Found") -> Whiteboard | C23: =IFERROR(_xlfn.XLOOKUP(A23,'📦 Raw Data'!A$35:A$44,'📦 Raw Data'!C$35:C$44),"❌ Not Found") -> Stationary | D23: =IFERROR(_xlfn.XLOOKUP(A23,'📦 Raw Data'!A$35:A$44,'📦 Raw Data'!D$35:D$44),"❌ Not Found") -> 3200 | E23: =IFERROR(_xlfn.XLOOKUP(A23,'📦 Raw Data'!A$35:A$44,'📦 Raw Data'!E$35:E$44),"❌ Not Found") -> 1900 | F23: =IFERROR((D23-E23)/D23,"N/A") -> 0.40625
A24: P001 | B24: =IFERROR(_xlfn.XLOOKUP(A24,'📦 Raw Data'!A$35:A$44,'📦 Raw Data'!B$35:B$44),"❌ Not Found") -> Laptop Pro | C24: =IFERROR(_xlfn.XLOOKUP(A24,'📦 Raw Data'!A$35:A$44,'📦 Raw Data'!C$35:C$44),"❌ Not Found") -> Electronics | D24: =IFERROR(_xlfn.XLOOKUP(A24,'📦 Raw Data'!A$35:A$44,'📦 Raw Data'!D$35:D$44),"❌ Not Found") -> 85000 | E24: =IFERROR(_xlfn.XLOOKUP(A24,'📦 Raw Data'!A$35:A$44,'📦 Raw Data'!E$35:E$44),"❌ Not Found") -> 65000 | F24: =IFERROR((D24-E24)/D24,"N/A") -> 0.23529412
A25: P099 | B25: =IFERROR(_xlfn.XLOOKUP(A25,'📦 Raw Data'!A$35:A$44,'📦 Raw Data'!B$35:B$44),"❌ Not Found") -> ❌ Not Found | C25: =IFERROR(_xlfn.XLOOKUP(A25,'📦 Raw Data'!A$35:A$44,'📦 Raw Data'!C$35:C$44),"❌ Not Found") -> ❌ Not Found | D25: =IFERROR(_xlfn.XLOOKUP(A25,'📦 Raw Data'!A$35:A$44,'📦 Raw Data'!D$35:D$44),"❌ Not Found") -> ❌ Not Found | E25: =IFERROR(_xlfn.XLOOKUP(A25,'📦 Raw Data'!A$35:A$44,'📦 Raw Data'!E$35:E$44),"❌ Not Found") -> ❌ Not Found | F25: =IFERROR((D25-E25)/D25,"N/A") -> N/A
A27: 💡 Key Tips
A28: 1. Use "❌ Not Found" as the 4th argument instead of wrapping in IFERROR — cleaner!
A29: 2. To search from bottom: set search_mode to -1
A30: 3. XLOOKUP works across sheets — just prefix the range with SheetName!
A31: 4. For approximate match (e.g., grade ranges) set match_mode to 1 or -1

Sheet 🎯 INDEX-MATCH
A1: 🎯 INDEX + MATCH — The Power Combo
A3: 📖 How INDEX-MATCH Works
A4: MATCH syntax: | C4: '=MATCH(lookup_value, lookup_array, [match_type]) → Returns the POSITION (row/col number)
A5: INDEX syntax: | C5: '=INDEX(array, row_num, [col_num]) → Returns the VALUE at a given position
A6: Combined: | C6: '=INDEX(return_range, MATCH(lookup_value, search_range, 0)) → Returns value after finding position
A7: match_type=0: | C7: Exact match (always use 0 for lookups)
A8: vs VLOOKUP: | C8: ✅ Can look LEFT of search column ✅ Column order doesn't matter ✅ More flexible with dynamic ranges
A10: EXAMPLE 1 — Find Employee Info by Name (Left Lookup — impossible in VLOOKUP!)
A11: Employee Name | B11: Emp ID | C11: Department | D11: Base Salary | E11: Sales Amount
A12: Karan Joshi | B12: =IFERROR(INDEX('📦 Raw Data'!A$6:A$30,MATCH(A12,'📦 Raw Data'!B$6:B$30,0)),"Not Found") -> E005 | C12: =IFERROR(INDEX('📦 Raw Data'!C$6:C$30,MATCH(A12,'📦 Raw Data'!B$6:B$30,0)),"N/A") -> Sales | D12: =IFERROR(INDEX('📦 Raw Data'!F$6:F$30,MATCH(A12,'📦 Raw Data'!B$6:B$30,0)),"N/A") -> 91000 | E12: =IFERROR(INDEX('📦 Raw Data'!G$6:G$30,MATCH(A12,'📦 Raw Data'!B$6:B$30,0)),"N/A") -> 162000
A13: Rajesh Pandey | B13: =IFERROR(INDEX('📦 Raw Data'!A$6:A$30,MATCH(A13,'📦 Raw Data'!B$6:B$30,0)),"Not Found") -> E013 | C13: =IFERROR(INDEX('📦 Raw Data'!C$6:C$30,MATCH(A13,'📦 Raw Data'!B$6:B$30,0)),"N/A") -> Sales | D13: =IFERROR(INDEX('📦 Raw Data'!F$6:F$30,MATCH(A13,'📦 Raw Data'!B$6:B$30,0)),"N/A") -> 88000 | E13: =IFERROR(INDEX('📦 Raw Data'!G$6:G$30,MATCH(A13,'📦 Raw Data'!B$6:B$30,0)),"N/A") -> 175000
A14: Meera Nair | B14: =IFERROR(INDEX('📦 Raw Data'!A$6:A$30,MATCH(A14,'📦 Raw Data'!B$6:B$30,0)),"Not Found") -> E010 | C14: =IFERROR(INDEX('📦 Raw Data'!C$6:C$30,MATCH(A14,'📦 Raw Data'!B$6:B$30,0)),"N/A") -> Marketing | D14: =IFERROR(INDEX('📦 Raw Data'!F$6:F$30,MATCH(A14,'📦 Raw Data'!B$6:B$30,0)),"N/A") -> 74000 | E14: =IFERROR(INDEX('📦 Raw Data'!G$6:G$30,MATCH(A14,'📦 Raw Data'!B$6:B$30,0)),"N/A") -> 0
A15: Amit Shah | B15: =IFERROR(INDEX('📦 Raw Data'!A$6:A$30,MATCH(A15,'📦 Raw Data'!B$6:B$30,0)),"Not Found") -> E001 | C15: =IFERROR(INDEX('📦 Raw Data'!C$6:C$30,MATCH(A15,'📦 Raw Data'!B$6:B$30,0)),"N/A") -> Sales | D15: =IFERROR(INDEX('📦 Raw Data'!F$6:F$30,MATCH(A15,'📦 Raw Data'!B$6:B$30,0)),"N/A") -> 82000 | E15: =IFERROR(INDEX('📦 Raw Data'!G$6:G$30,MATCH(A15,'📦 Raw Data'!B$6:B$30,0)),"N/A") -> 145000
A16: Unknown Person | B16: =IFERROR(INDEX('📦 Raw Data'!A$6:A$30,MATCH(A16,'📦 Raw Data'!B$6:B$30,0)),"Not Found") -> Not Found | C16: =IFERROR(INDEX('📦 Raw Data'!C$6:C$30,MATCH(A16,'📦 Raw Data'!B$6:B$30,0)),"N/A") -> N/A | D16: =IFERROR(INDEX('📦 Raw Data'!F$6:F$30,MATCH(A16,'📦 Raw Data'!B$6:B$30,0)),"N/A") -> N/A | E16: =IFERROR(INDEX('📦 Raw Data'!G$6:G$30,MATCH(A16,'📦 Raw Data'!B$6:B$30,0)),"N/A") -> N/A
A18: EXAMPLE 2 — Two-Criteria Match (Department + Region → Highest Salary)
A19: Department | B19: Region | C19: Count in Group | D19: Total Sales | E19: Avg Base Salary
A20: Sales | B20: North | C20: =COUNTIFS('📦 Raw Data'!C$6:C$30,A20,'📦 Raw Data'!D$6:D$30,B20) -> 4 | D20: =SUMIFS('📦 Raw Data'!G$6:G$30,'📦 Raw Data'!C$6:C$30,A20,'📦 Raw Data'!D$6:D$30,B20) -> 523000 | E20: =IFERROR(AVERAGEIFS('📦 Raw Data'!F$6:F$30,'📦 Raw Data'!C$6:C$30,A20,'📦 Raw Data'!D$6:D$30,B20),"No Data") -> 75750
A21: Sales | B21: South | C21: =COUNTIFS('📦 Raw Data'!C$6:C$30,A21,'📦 Raw Data'!D$6:D$30,B21) -> 3 | D21: =SUMIFS('📦 Raw Data'!G$6:G$30,'📦 Raw Data'!C$6:C$30,A21,'📦 Raw Data'!D$6:D$30,B21) -> 232000 | E21: =IFERROR(AVERAGEIFS('📦 Raw Data'!F$6:F$30,'📦 Raw Data'!C$6:C$30,A21,'📦 Raw Data'!D$6:D$30,B21),"No Data") -> 47000
A22: IT | B22: West | C22: =COUNTIFS('📦 Raw Data'!C$6:C$30,A22,'📦 Raw Data'!D$6:D$30,B22) -> 2 | D22: =SUMIFS('📦 Raw Data'!G$6:G$30,'📦 Raw Data'!C$6:C$30,A22,'📦 Raw Data'!D$6:D$30,B22) -> 0 | E22: =IFERROR(AVERAGEIFS('📦 Raw Data'!F$6:F$30,'📦 Raw Data'!C$6:C$30,A22,'📦 Raw Data'!D$6:D$30,B22),"No Data") -> 70500
A23: Marketing | B23: West | C23: =COUNTIFS('📦 Raw Data'!C$6:C$30,A23,'📦 Raw Data'!D$6:D$30,B23) -> 1 | D23: =SUMIFS('📦 Raw Data'!G$6:G$30,'📦 Raw Data'!C$6:C$30,A23,'📦 Raw Data'!D$6:D$30,B23) -> 0 | E23: =IFERROR(AVERAGEIFS('📦 Raw Data'!F$6:F$30,'📦 Raw Data'!C$6:C$30,A23,'📦 Raw Data'!D$6:D$30,B23),"No Data") -> 45000
A24: Finance | B24: South | C24: =COUNTIFS('📦 Raw Data'!C$6:C$30,A24,'📦 Raw Data'!D$6:D$30,B24) -> 1 | D24: =SUMIFS('📦 Raw Data'!G$6:G$30,'📦 Raw Data'!C$6:C$30,A24,'📦 Raw Data'!D$6:D$30,B24) -> 0 | E24: =IFERROR(AVERAGEIFS('📦 Raw Data'!F$6:F$30,'📦 Raw Data'!C$6:C$30,A24,'📦 Raw Data'!D$6:D$30,B24),"No Data") -> 85000
A26: 💡 Key Tips
A27: 1. INDEX-MATCH never breaks when you insert/delete columns — VLOOKUP does!
A29: 3. Wrap the whole formula in IFERROR to handle missing values gracefully.
A30: 4. For 2D lookup: =INDEX(table, MATCH(row_val, row_range,0), MATCH(col_val, col_range,0))

Sheet 🌿 Nested IFS
A1: 🌿 NESTED IFS — Conditional Logic Builder
A3: 📖 IF vs IFS vs Nested IF
A4: Basic IF: | C4: '=IF(condition, value_if_true, value_if_false)
A5: Nested IF: | C5: '=IF(cond1, VAL1, IF(cond2, VAL2, IF(cond3, VAL3, default)))
A6: IFS function: | C6: '=ifs(cond1, VAL1, cond2, VAL2, cond3, VAL3, TRUE(), default) ← Cleaner in Excel 2019+
A7: When to use: | C7: When you need to assign categories, grades, labels, or tiers based on multiple conditions
A8: Tip: | C8: Use IFS() for 3+ conditions — much easier to read than deeply nested IF
A10: EXAMPLE 1 — Performance Rating based on Sales Amount
A11: Rules: <50K=Low | 50K–99K=Medium | 100K–149K=High | ≥150K=Exceptional | 0=No Sales Role
A12: Emp ID | B12: Name | C12: Department | D12: Sales Amount | E12: Nested IF Rating | F12: IFS Rating | G12: Bonus Earned
A13: E001 | B13: Amit Shah | C13: Sales | D13: 5500 | E13: =IF(D13=0,"No Sales Role",IF(D13<50000,"Low",IF(D13<100000,"Medium",IF(D13<150000,"High","Exceptional")))) -> Low | F13: =IF(D13=0,"No Sales Role",IF(D13<50000,"Low",IF(D13<100000,"Medium",IF(D13<150000,"High","Exceptional")))) -> Low | G13: =IF(D13=0,0,IF(D13>=150000,D13*20%,IF(D13>=100000,D13*15%,IF(D13>=50000,D13*10%,D13*5%)))) -> 275 | I13: =IF(D13>50000,"good",(IF(D13<5000,"intern","emp"))) -> emp
A14: E002 | B14: Priya Patel | C14: Marketing | D14: 0 | E14: =IF(D14=0,"No Sales Role",IF(D14<50000,"Low",IF(D14<100000,"Medium",IF(D14<150000,"High","Exceptional")))) -> No Sales Role | F14: =IF(D14=0,"No Sales Role",IF(D14<50000,"Low",IF(D14<100000,"Medium",IF(D14<150000,"High","Exceptional")))) -> No Sales Role | G14: =IF(D14=0,0,IF(D14>=150000,D14*20%,IF(D14>=100000,D14*15%,IF(D14>=50000,D14*10%,D14*5%)))) -> 0 | I14: =IF(D14>50000,"good","not good") -> not good
A15: E003 | B15: Ravi Kumar | C15: Sales | D15: 98000 | E15: =IF(D15=0,"No Sales Role",IF(D15<50000,"Low",IF(D15<100000,"Medium",IF(D15<150000,"High","Exceptional")))) -> Medium | F15: =IF(D15=0,"No Sales Role",IF(D15<50000,"Low",IF(D15<100000,"Medium",IF(D15<150000,"High","Exceptional")))) -> Medium | G15: =IF(D15=0,0,IF(D15>=150000,D15*20%,IF(D15>=100000,D15*15%,IF(D15>=50000,D15*10%,D15*5%)))) -> 9800 | I15: =IF(D15>50000,"good","not good") -> good
A16: E004 | B16: Sneha Mehta | C16: IT | D16: 0 | E16: =IF(D16=0,"No Sales Role",IF(D16<50000,"Low",IF(D16<100000,"Medium",IF(D16<150000,"High","Exceptional")))) -> No Sales Role | F16: =IF(D16=0,"No Sales Role",IF(D16<50000,"Low",IF(D16<100000,"Medium",IF(D16<150000,"High","Exceptional")))) -> No Sales Role | G16: =IF(D16=0,0,IF(D16>=150000,D16*20%,IF(D16>=100000,D16*15%,IF(D16>=50000,D16*10%,D16*5%)))) -> 0 | I16: =IF(D16>50000,"good","not good") -> not good
A17: E005 | B17: Karan Joshi | C17: Sales | D17: 162000 | E17: =IF(D17=0,"No Sales Role",IF(D17<50000,"Low",IF(D17<100000,"Medium",IF(D17<150000,"High","Exceptional")))) -> Exceptional | F17: =IF(D17=0,"No Sales Role",IF(D17<50000,"Low",IF(D17<100000,"Medium",IF(D17<150000,"High","Exceptional")))) -> Exceptional | G17: =IF(D17=0,0,IF(D17>=150000,D17*20%,IF(D17>=100000,D17*15%,IF(D17>=50000,D17*10%,D17*5%)))) -> 32400 | I17: =IF(D17>50000,"good","not good") -> good
A18: E006 | B18: Divya Sharma | C18: HR | D18: 0 | E18: =IF(D18=0,"No Sales Role",IF(D18<50000,"Low",IF(D18<100000,"Medium",IF(D18<150000,"High","Exceptional")))) -> No Sales Role | F18: =IF(D18=0,"No Sales Role",IF(D18<50000,"Low",IF(D18<100000,"Medium",IF(D18<150000,"High","Exceptional")))) -> No Sales Role | G18: =IF(D18=0,0,IF(D18>=150000,D18*20%,IF(D18>=100000,D18*15%,IF(D18>=50000,D18*10%,D18*5%)))) -> 0 | I18: =IF(D18>50000,"good","not good") -> not good
A19: E007 | B19: Ankit Gupta | C19: Sales | D19: 54000 | E19: =IF(D19=0,"No Sales Role",IF(D19<50000,"Low",IF(D19<100000,"Medium",IF(D19<150000,"High","Exceptional")))) -> Medium | F19: =IF(D19=0,"No Sales Role",IF(D19<50000,"Low",IF(D19<100000,"Medium",IF(D19<150000,"High","Exceptional")))) -> Medium | G19: =IF(D19=0,0,IF(D19>=150000,D19*20%,IF(D19>=100000,D19*15%,IF(D19>=50000,D19*10%,D19*5%)))) -> 5400 | I19: =IF(D19>50000,"good","not good") -> good
A20: E008 | B20: Neha Singh | C20: Finance | D20: 0 | E20: =IF(D20=0,"No Sales Role",IF(D20<50000,"Low",IF(D20<100000,"Medium",IF(D20<150000,"High","Exceptional")))) -> No Sales Role | F20: =IF(D20=0,"No Sales Role",IF(D20<50000,"Low",IF(D20<100000,"Medium",IF(D20<150000,"High","Exceptional")))) -> No Sales Role | G20: =IF(D20=0,0,IF(D20>=150000,D20*20%,IF(D20>=100000,D20*15%,IF(D20>=50000,D20*10%,D20*5%)))) -> 0 | I20: =IF(D20>50000,"good","not good") -> not good
A21: E009 | B21: Vikram Rao | C21: Sales | D21: 112000 | E21: =IF(D21=0,"No Sales Role",IF(D21<50000,"Low",IF(D21<100000,"Medium",IF(D21<150000,"High","Exceptional")))) -> High | F21: =IF(D21=0,"No Sales Role",IF(D21<50000,"Low",IF(D21<100000,"Medium",IF(D21<150000,"High","Exceptional")))) -> High | G21: =IF(D21=0,0,IF(D21>=150000,D21*20%,IF(D21>=100000,D21*15%,IF(D21>=50000,D21*10%,D21*5%)))) -> 16800 | I21: =IF(D21>50000,"good","not good") -> good
A22: E010 | B22: Meera Nair | C22: Marketing | D22: 0 | E22: =IF(D22=0,"No Sales Role",IF(D22<50000,"Low",IF(D22<100000,"Medium",IF(D22<150000,"High","Exceptional")))) -> No Sales Role | F22: =IF(D22=0,"No Sales Role",IF(D22<50000,"Low",IF(D22<100000,"Medium",IF(D22<150000,"High","Exceptional")))) -> No Sales Role | G22: =IF(D22=0,0,IF(D22>=150000,D22*20%,IF(D22>=100000,D22*15%,IF(D22>=50000,D22*10%,D22*5%)))) -> 0 | I22: =IF(D22>50000,"good","not good") -> not good
A23: E011 | B23: Sanjay Verma | C23: Sales | D23: 63000 | E23: =IF(D23=0,"No Sales Role",IF(D23<50000,"Low",IF(D23<100000,"Medium",IF(D23<150000,"High","Exceptional")))) -> Medium | F23: =IF(D23=0,"No Sales Role",IF(D23<50000,"Low",IF(D23<100000,"Medium",IF(D23<150000,"High","Exceptional")))) -> Medium | G23: =IF(D23=0,0,IF(D23>=150000,D23*20%,IF(D23>=100000,D23*15%,IF(D23>=50000,D23*10%,D23*5%)))) -> 6300 | I23: =IF(D23>50000,"good","not good") -> good
A24: E012 | B24: Pooja Agarwal | C24: IT | D24: 0 | E24: =IF(D24=0,"No Sales Role",IF(D24<50000,"Low",IF(D24<100000,"Medium",IF(D24<150000,"High","Exceptional")))) -> No Sales Role | F24: =IF(D24=0,"No Sales Role",IF(D24<50000,"Low",IF(D24<100000,"Medium",IF(D24<150000,"High","Exceptional")))) -> No Sales Role | G24: =IF(D24=0,0,IF(D24>=150000,D24*20%,IF(D24>=100000,D24*15%,IF(D24>=50000,D24*10%,D24*5%)))) -> 0 | I24: =IF(D24>50000,"good","not good") -> not good
A25: E013 | B25: Rajesh Pandey | C25: Sales | D25: 175000 | E25: =IF(D25=0,"No Sales Role",IF(D25<50000,"Low",IF(D25<100000,"Medium",IF(D25<150000,"High","Exceptional")))) -> Exceptional | F25: =IF(D25=0,"No Sales Role",IF(D25<50000,"Low",IF(D25<100000,"Medium",IF(D25<150000,"High","Exceptional")))) -> Exceptional | G25: =IF(D25=0,0,IF(D25>=150000,D25*20%,IF(D25>=100000,D25*15%,IF(D25>=50000,D25*10%,D25*5%)))) -> 35000 | I25: =IF(D25>50000,"good","not good") -> good
... A37: E025 | B37: Gaurav Saxena | C37: Sales | D37: 58000 | E37: =IF(D37=0,"No Sales Role",IF(D37<50000,"Low",IF(D37<100000,"Medium",IF(D37<150000,"High","Exceptional")))) -> Medium | F37: =IF(D37=0,"No Sales Role",IF(D37<50000,"Low",IF(D37<100000,"Medium",IF(D37<150000,"High","Exceptional")))) -> Medium | G37: =IF(D37=0,0,IF(D37>=150000,D37*20%,IF(D37>=100000,D37*15%,IF(D37>=50000,D37*10%,D37*5%)))) -> 5800 | I37: =IF(D37>50000,"good","not good") -> good
I38: =IF(D38>50000,"good","not good") -> not good
A39: 💡 Key Tips
A40: 1. Keep nesting to max 3 levels — beyond that, use IFS() or CHOOSE() for readability.
A41: 2. Order matters in nested IF: check from smallest to largest OR largest to smallest — be consistent.
A42: 3. IFS() doesn't need a TRUE final condition but it's best practice to add TRUE, "Other" as a catch-all.
A43: 4. Combine with AND/OR for multi-condition checks: =IF(AND(A1>50, B1="Active"), "VIP", "Standard")

Sheet ➕ SUMIFS
A1: ➕ SUMIFS — Sum with Multiple Conditions
A3: 📖 SUMIF vs SUMIFS
A4: SUMIF syntax: | C4: '=SUMIF(criteria_range, criteria, sum_range) → One condition only
A5: SUMIFS syntax: | C5: '=SUMIFS(sum_range, range1, crit1, range2, crit2, ...) → Multiple conditions
A6: Key difference: | C6: In SUMIFS, the SUM range comes FIRST — opposite of SUMIF!
A7: Use case: | C7: Total sales by department + region + year, budget analysis, conditional aggregation
A9: EXAMPLE 1 — Department × Region Sales Summary
A10: Department \ Region | B10: North | C10: South | D10: East | E10: West | F10: Grand Total
A11: Sales | B11: =SUMIFS('📦 Raw Data'!G$6:G$30,'📦 Raw Data'!C$6:C$30,A11,'📦 Raw Data'!D$6:D$30,B$10) -> 523000 | C11: =SUMIFS('📦 Raw Data'!G$6:G$30,'📦 Raw Data'!C$6:C$30,A11,'📦 Raw Data'!D$6:D$30,C$10) -> 232000 | D11: =SUMIFS('📦 Raw Data'!G$6:G$30,'📦 Raw Data'!C$6:C$30,A11,'📦 Raw Data'!D$6:D$30,D$10) -> 352000 | E11: =SUMIFS('📦 Raw Data'!G$6:G$30,'📦 Raw Data'!C$6:C$30,A11,'📦 Raw Data'!D$6:D$30,E$10) -> 360000 | F11: =SUM(B11:E11) -> 1467000
A12: Marketing | B12: =SUMIFS('📦 Raw Data'!G$6:G$30,'📦 Raw Data'!C$6:C$30,A12,'📦 Raw Data'!D$6:D$30,B$10) -> 0 | C12: =SUMIFS('📦 Raw Data'!G$6:G$30,'📦 Raw Data'!C$6:C$30,A12,'📦 Raw Data'!D$6:D$30,C$10) -> 0 | D12: =SUMIFS('📦 Raw Data'!G$6:G$30,'📦 Raw Data'!C$6:C$30,A12,'📦 Raw Data'!D$6:D$30,D$10) -> 0 | E12: =SUMIFS('📦 Raw Data'!G$6:G$30,'📦 Raw Data'!C$6:C$30,A12,'📦 Raw Data'!D$6:D$30,E$10) -> 0 | F12: =SUM(B12:E12) -> 0
A13: IT | B13: =SUMIFS('📦 Raw Data'!G$6:G$30,'📦 Raw Data'!C$6:C$30,A13,'📦 Raw Data'!D$6:D$30,B$10) -> 0 | C13: =SUMIFS('📦 Raw Data'!G$6:G$30,'📦 Raw Data'!C$6:C$30,A13,'📦 Raw Data'!D$6:D$30,C$10) -> 0 | D13: =SUMIFS('📦 Raw Data'!G$6:G$30,'📦 Raw Data'!C$6:C$30,A13,'📦 Raw Data'!D$6:D$30,D$10) -> 0 | E13: =SUMIFS('📦 Raw Data'!G$6:G$30,'📦 Raw Data'!C$6:C$30,A13,'📦 Raw Data'!D$6:D$30,E$10) -> 0 | F13: =SUM(B13:E13) -> 0
A14: HR | B14: =SUMIFS('📦 Raw Data'!G$6:G$30,'📦 Raw Data'!C$6:C$30,A14,'📦 Raw Data'!D$6:D$30,B$10) -> 0 | C14: =SUMIFS('📦 Raw Data'!G$6:G$30,'📦 Raw Data'!C$6:C$30,A14,'📦 Raw Data'!D$6:D$30,C$10) -> 0 | D14: =SUMIFS('📦 Raw Data'!G$6:G$30,'📦 Raw Data'!C$6:C$30,A14,'📦 Raw Data'!D$6:D$30,D$10) -> 0 | E14: =SUMIFS('📦 Raw Data'!G$6:G$30,'📦 Raw Data'!C$6:C$30,A14,'📦 Raw Data'!D$6:D$30,E$10) -> 0 | F14: =SUM(B14:E14) -> 0
A15: Finance | B15: =SUMIFS('📦 Raw Data'!G$6:G$30,'📦 Raw Data'!C$6:C$30,A15,'📦 Raw Data'!D$6:D$30,B$10) -> 0 | C15: =SUMIFS('📦 Raw Data'!G$6:G$30,'📦 Raw Data'!C$6:C$30,A15,'📦 Raw Data'!D$6:D$30,C$10) -> 0 | D15: =SUMIFS('📦 Raw Data'!G$6:G$30,'📦 Raw Data'!C$6:C$30,A15,'📦 Raw Data'!D$6:D$30,D$10) -> 0 | E15: =SUMIFS('📦 Raw Data'!G$6:G$30,'📦 Raw Data'!C$6:C$30,A15,'📦 Raw Data'!D$6:D$30,E$10) -> 0 | F15: =SUM(B15:E15) -> 0
A16: GRAND TOTAL | B16: =SUM(B11:B15) -> 523000 | C16: =SUM(C11:C15) -> 232000 | D16: =SUM(D11:D15) -> 352000 | E16: =SUM(E11:E15) -> 360000 | F16: =SUM(F11:F15) -> 1467000
A18: EXAMPLE 2 — Salary Budget: Active Senior Employees by Department
A19: Department | B19: Count (Active+Senior) | C19: Total Salary Budget | D19: Avg Salary | E19: Total Sales | F19: Sales vs Salary Ratio
A20: Sales | B20: =COUNTIFS('📦 Raw Data'!C$6:C$30,A20,'📦 Raw Data'!E$6:E$30,"Senior",'📦 Raw Data'!J$6:J$30,"Active") -> 5 | C20: =SUMIFS('📦 Raw Data'!F$6:F$30,'📦 Raw Data'!C$6:C$30,A20,'📦 Raw Data'!E$6:E$30,"Senior",'📦 Raw Data'!J$6:J$30,"Active") -> 443000 | D20: =IFERROR(AVERAGEIFS('📦 Raw Data'!F$6:F$30,'📦 Raw Data'!C$6:C$30,A20,'📦 Raw Data'!E$6:E$30,"Senior",'📦 Raw Data'!J$6:J$30,"Active"),0) -> 88600 | E20: =SUMIFS('📦 Raw Data'!G$6:G$30,'📦 Raw Data'!C$6:C$30,A20,'📦 Raw Data'!E$6:E$30,"Senior",'📦 Raw Data'!J$6:J$30,"Active") -> 781000 | F20: =IFERROR(E20/C20,"N/A") -> 1.7629797
A21: Marketing | B21: =COUNTIFS('📦 Raw Data'!C$6:C$30,A21,'📦 Raw Data'!E$6:E$30,"Senior",'📦 Raw Data'!J$6:J$30,"Active") -> 1 | C21: =SUMIFS('📦 Raw Data'!F$6:F$30,'📦 Raw Data'!C$6:C$30,A21,'📦 Raw Data'!E$6:E$30,"Senior",'📦 Raw Data'!J$6:J$30,"Active") -> 74000 | D21: =IFERROR(AVERAGEIFS('📦 Raw Data'!F$6:F$30,'📦 Raw Data'!C$6:C$30,A21,'📦 Raw Data'!E$6:E$30,"Senior",'📦 Raw Data'!J$6:J$30,"Active"),0) -> 74000 | E21: =SUMIFS('📦 Raw Data'!G$6:G$30,'📦 Raw Data'!C$6:C$30,A21,'📦 Raw Data'!E$6:E$30,"Senior",'📦 Raw Data'!J$6:J$30,"Active") -> 0 | F21: =IFERROR(E21/C21,"N/A") -> 0
A22: IT | B22: =COUNTIFS('📦 Raw Data'!C$6:C$30,A22,'📦 Raw Data'!E$6:E$30,"Senior",'📦 Raw Data'!J$6:J$30,"Active") -> 2 | C22: =SUMIFS('📦 Raw Data'!F$6:F$30,'📦 Raw Data'!C$6:C$30,A22,'📦 Raw Data'!E$6:E$30,"Senior",'📦 Raw Data'!J$6:J$30,"Active") -> 160000 | D22: =IFERROR(AVERAGEIFS('📦 Raw Data'!F$6:F$30,'📦 Raw Data'!C$6:C$30,A22,'📦 Raw Data'!E$6:E$30,"Senior",'📦 Raw Data'!J$6:J$30,"Active"),0) -> 80000 | E22: =SUMIFS('📦 Raw Data'!G$6:G$30,'📦 Raw Data'!C$6:C$30,A22,'📦 Raw Data'!E$6:E$30,"Senior",'📦 Raw Data'!J$6:J$30,"Active") -> 0 | F22: =IFERROR(E22/C22,"N/A") -> 0
A23: HR | B23: =COUNTIFS('📦 Raw Data'!C$6:C$30,A23,'📦 Raw Data'!E$6:E$30,"Senior",'📦 Raw Data'!J$6:J$30,"Active") -> 1 | C23: =SUMIFS('📦 Raw Data'!F$6:F$30,'📦 Raw Data'!C$6:C$30,A23,'📦 Raw Data'!E$6:E$30,"Senior",'📦 Raw Data'!J$6:J$30,"Active") -> 71000 | D23: =IFERROR(AVERAGEIFS('📦 Raw Data'!F$6:F$30,'📦 Raw Data'!C$6:C$30,A23,'📦 Raw Data'!E$6:E$30,"Senior",'📦 Raw Data'!J$6:J$30,"Active"),0) -> 71000 | E23: =SUMIFS('📦 Raw Data'!G$6:G$30,'📦 Raw Data'!C$6:C$30,A23,'📦 Raw Data'!E$6:E$30,"Senior",'📦 Raw Data'!J$6:J$30,"Active") -> 0 | F23: =IFERROR(E23/C23,"N/A") -> 0
A24: Finance | B24: =COUNTIFS('📦 Raw Data'!C$6:C$30,A24,'📦 Raw Data'!E$6:E$30,"Senior",'📦 Raw Data'!J$6:J$30,"Active") -> 1 | C24: =SUMIFS('📦 Raw Data'!F$6:F$30,'📦 Raw Data'!C$6:C$30,A24,'📦 Raw Data'!E$6:E$30,"Senior",'📦 Raw Data'!J$6:J$30,"Active") -> 85000 | D24: =IFERROR(AVERAGEIFS('📦 Raw Data'!F$6:F$30,'📦 Raw Data'!C$6:C$30,A24,'📦 Raw Data'!E$6:E$30,"Senior",'📦 Raw Data'!J$6:J$30,"Active"),0) -> 85000 | E24: =SUMIFS('📦 Raw Data'!G$6:G$30,'📦 Raw Data'!C$6:C$30,A24,'📦 Raw Data'!E$6:E$30,"Senior",'📦 Raw Data'!J$6:J$30,"Active") -> 0 | F24: =IFERROR(E24/C24,"N/A") -> 0
A26: 💡 Key Tips
A27: 1. Sum range FIRST in SUMIFS, but criteria range FIRST in SUMIF — common mistake!
A28: 2. Use wildcards: "Sales*" matches anything starting with 'Sales'; "*Manager*" matches if contains 'Manager'
A29: 3. Use comparison operators in quotes: ">50000" or "<>Inactive" as criteria strings
A30: 4. SUMPRODUCT can replace SUMIFS for complex array-based conditions: =SUMPRODUCT((C:C="Sales")*(D:D="North")*G:G)

Sheet 🛡️ IFERROR
A1: 🛡️ IFERROR — Graceful Error Handling
A3: 📖 Understanding IFERROR
A4: Syntax: | C4: '=IFERROR(value, value_if_error)
A5: What it catches: | C5: Catches these Excel error types: N/A, VALUE!, REF!, DIV/0!, NUM!, NAME?, NULL!
A6: IFNA vs IFERROR: | C6: Use IFNA when you want only lookup errors caught; IFERROR for all errors
A7: Best practice: | C7: Add IFERROR LAST, after the inner formula works — don't use it to hide bugs!
A9: EXAMPLE 1 — Error Scenarios Side-by-Side
A10: Scenario | B10: Without IFERROR (raw) | C10: With IFERROR (clean) | D10: Notes
A11: Division by zero | B11: WITHOUT IFERROR: =A1/0 gives error | C11: =IFERROR(1/0,"Cannot divide by zero") -> Cannot divide by zero | D11: Intentional error demo — IFERROR wraps this
A12: ID not in lookup | B12: WITHOUT IFERROR: XLOOKUP for missing ID gives error | C12: =IFERROR(_xludf.xlookup("E999",'📦 Raw Data'!A$6:A$30,'📦 Raw Data'!B$6:B$30),"Not Found") -> Not Found | D12: Looking up ID that doesn't exist
A13: Empty cell division | B13: WITHOUT IFERROR: dividing by blank cell gives error | C13: =IFERROR(G6/0,0) -> 0 | D13: Sales/Salary ratio when either is 0 or blank
A14: MATCH for missing value | B14: WITHOUT IFERROR: MATCH for non-existent value gives error | C14: =IFERROR(MATCH("ZZZZ",'📦 Raw Data'!B$6:B$30,0),"No match found") -> No match found | D14: =IFERROR(MATCH("ZZZZ",'📦 Raw Data'!B$6:B$30,0),"No match found") -> No match found
A15: Index out of range | B15: WITHOUT IFERROR: INDEX beyond range gives error | C15: =IFERROR(INDEX('📦 Raw Data'!A$6:A$15,99),"Row out of range") -> Row out of range | D15: Asking for row 99 in a 6-row array
A17: EXAMPLE 2 — Full Formula with IFERROR: Commission Calculator
A18: Emp ID | B18: Name | C18: Sales | D18: Base Salary | E18: Commission Rate | F18: Commission ₹ | G18: Salary+Commission | H18: Pct Increase
A19: E001 | B19: Amit Shah | C19: 145000 | D19: 82000 | E19: =IFERROR(_xludf.xlookup(A19,'📦 Raw Data'!A$6:A$30,'📦 Raw Data'!K$6:K$30),"5%") -> 5% | F19: =IFERROR(C19*E19,0) -> 7250 | G19: =IFERROR(D19+F19,D19) -> 89250 | H19: =IFERROR(F19/D19,"N/A") -> 0.088414634
A20: E002 | B20: Priya Patel | C20: 0 | D20: 45000 | E20: =IFERROR(_xludf.xlookup(A20,'📦 Raw Data'!A$6:A$30,'📦 Raw Data'!K$6:K$30),"5%") -> 5% | F20: =IFERROR(C20*E20,0) -> 0 | G20: =IFERROR(D20+F20,D20) -> 45000 | H20: =IFERROR(F20/D20,"N/A") -> 0
A21: E003 | B21: Ravi Kumar | C21: 98000 | D21: 61000 | E21: =IFERROR(_xludf.xlookup(A21,'📦 Raw Data'!A$6:A$30,'📦 Raw Data'!K$6:K$30),"5%") -> 5% | F21: =IFERROR(C21*E21,0) -> 4900 | G21: =IFERROR(D21+F21,D21) -> 65900 | H21: =IFERROR(F21/D21,"N/A") -> 0.080327869
A22: E004 | B22: Sneha Mehta | C22: 0 | D22: 78000 | E22: =IFERROR(_xludf.xlookup(A22,'📦 Raw Data'!A$6:A$30,'📦 Raw Data'!K$6:K$30),"5%") -> 5% | F22: =IFERROR(C22*E22,0) -> 0 | G22: =IFERROR(D22+F22,D22) -> 78000 | H22: =IFERROR(F22/D22,"N/A") -> 0
A23: E005 | B23: Karan Joshi | C23: 162000 | D23: 91000 | E23: =IFERROR(_xludf.xlookup(A23,'📦 Raw Data'!A$6:A$30,'📦 Raw Data'!K$6:K$30),"5%") -> 5% | F23: =IFERROR(C23*E23,0) -> 8100 | G23: =IFERROR(D23+F23,D23) -> 99100 | H23: =IFERROR(F23/D23,"N/A") -> 0.089010989
A24: E006 | B24: Divya Sharma | C24: 0 | D24: 52000 | E24: =IFERROR(_xludf.xlookup(A24,'📦 Raw Data'!A$6:A$30,'📦 Raw Data'!K$6:K$30),"5%") -> 5% | F24: =IFERROR(C24*E24,0) -> 0 | G24: =IFERROR(D24+F24,D24) -> 52000 | H24: =IFERROR(F24/D24,"N/A") -> 0
A25: E007 | B25: Ankit Gupta | C25: 54000 | D25: 38000 | E25: =IFERROR(_xludf.xlookup(A25,'📦 Raw Data'!A$6:A$30,'📦 Raw Data'!K$6:K$30),"5%") -> 5% | F25: =IFERROR(C25*E25,0) -> 2700 | G25: =IFERROR(D25+F25,D25) -> 40700 | H25: =IFERROR(F25/D25,"N/A") -> 0.071052632
A26: E008 | B26: Neha Singh | C26: 0 | D26: 85000 | E26: =IFERROR(_xludf.xlookup(A26,'📦 Raw Data'!A$6:A$30,'📦 Raw Data'!K$6:K$30),"5%") -> 5% | F26: =IFERROR(C26*E26,0) -> 0 | G26: =IFERROR(D26+F26,D26) -> 85000 | H26: =IFERROR(F26/D26,"N/A") -> 0
A27: E009 | B27: Vikram Rao | C27: 112000 | D27: 67000 | E27: =IFERROR(_xludf.xlookup(A27,'📦 Raw Data'!A$6:A$30,'📦 Raw Data'!K$6:K$30),"5%") -> 5% | F27: =IFERROR(C27*E27,0) -> 5600 | G27: =IFERROR(D27+F27,D27) -> 72600 | H27: =IFERROR(F27/D27,"N/A") -> 0.08358209
A28: E010 | B28: Meera Nair | C28: 0 | D28: 74000 | E28: =IFERROR(_xludf.xlookup(A28,'📦 Raw Data'!A$6:A$30,'📦 Raw Data'!K$6:K$30),"5%") -> 5% | F28: =IFERROR(C28*E28,0) -> 0 | G28: =IFERROR(D28+F28,D28) -> 74000 | H28: =IFERROR(F28/D28,"N/A") -> 0
A29: E011 | B29: Sanjay Verma | C29: 63000 | D29: 41000 | E29: =IFERROR(_xludf.xlookup(A29,'📦 Raw Data'!A$6:A$30,'📦 Raw Data'!K$6:K$30),"5%") -> 5% | F29: =IFERROR(C29*E29,0) -> 3150 | G29: =IFERROR(D29+F29,D29) -> 44150 | H29: =IFERROR(F29/D29,"N/A") -> 0.076829268
A30: E012 | B30: Pooja Agarwal | C30: 0 | D30: 59000 | E30: =IFERROR(_xludf.xlookup(A30,'📦 Raw Data'!A$6:A$30,'📦 Raw Data'!K$6:K$30),"5%") -> 5% | F30: =IFERROR(C30*E30,0) -> 0 | G30: =IFERROR(D30+F30,D30) -> 59000 | H30: =IFERROR(F30/D30,"N/A") -> 0
A32: 💡 Key Tips
A33: 1. Return 0 for numbers, "" for text, or a message like "N/A" — choose based on context.
A35: 3. Nested: =IFERROR(IFERROR(formula1, formula2), "Both failed") — try formula2 if formula1 errors
A36: 4. In SUMIFS/COUNTIFS you don't need IFERROR — they return 0 naturally when no match.

Sheet 📝 Practice Dataset
A1: 📝 PRACTICE DATASET — Student Exam Records (New Data to Practice)
A2: Apply all 5 formulas independently using this fresh dataset
A4: TABLE — Student Marks Dataset (Rows 5–25)
A5: Student ID | B5: Student Name | C5: Stream | D5: Class | E5: Math | F5: Science | G5: English | H5: Social Studies | I5: Attendance | J5: Average | K5: Grade | L5: Status
A6: S001 | B6: Aarav Jain | C6: Science | D6: 10-A | E6: 78 | F6: 82 | G6: 91 | H6: 88 | I6: Present | J6: =IFERROR(AVERAGE(E6:H6),0) -> 84.75 | K6: =IF(J6>=90,"A+",IF(J6>=80,"A",IF(J6>=70,"B",IF(J6>=60,"C",IF(J6>=50,"D","F"))))) -> A | L6: =IFERROR(IF(AND(J6>=50,I6="Present"),"PASS","Review"),"Error") -> PASS
A7: S002 | B7: Bhavna Rao | C7: Arts | D7: 11-B | E7: 55 | F7: 60 | G7: 48 | H7: 52 | I7: Present | J7: =IFERROR(AVERAGE(E7:H7),0) -> 53.75 | K7: =IF(J7>=90,"A+",IF(J7>=80,"A",IF(J7>=70,"B",IF(J7>=60,"C",IF(J7>=50,"D","F"))))) -> D | L7: =IFERROR(IF(AND(J7>=50,I7="Present"),"PASS","Review"),"Error") -> PASS
A8: S003 | B8: Chirag Modi | C8: Commerce | D8: 12-A | E8: 90 | F8: 88 | G8: 95 | H8: 92 | I8: Present | J8: =IFERROR(AVERAGE(E8:H8),0) -> 91.25 | K8: =IF(J8>=90,"A+",IF(J8>=80,"A",IF(J8>=70,"B",IF(J8>=60,"C",IF(J8>=50,"D","F"))))) -> A+ | L8: =IFERROR(IF(AND(J8>=50,I8="Present"),"PASS","Review"),"Error") -> PASS
A9: S004 | B9: Diya Patel | C9: Science | D9: 10-B | E9: 44 | F9: 50 | G9: 38 | H9: 42 | I9: Absent | J9: =IFERROR(AVERAGE(E9:H9),0) -> 43.5 | K9: =IF(J9>=90,"A+",IF(J9>=80,"A",IF(J9>=70,"B",IF(J9>=60,"C",IF(J9>=50,"D","F"))))) -> F | L9: =IFERROR(IF(AND(J9>=50,I9="Present"),"PASS","Review"),"Error") -> Review
A10: S005 | B10: Eshan Verma | C10: Arts | D10: 11-A | E10: 72 | F10: 68 | G10: 75 | H10: 70 | I10: Present | J10: =IFERROR(AVERAGE(E10:H10),0) -> 71.25 | K10: =IF(J10>=90,"A+",IF(J10>=80,"A",IF(J10>=70,"B",IF(J10>=60,"C",IF(J10>=50,"D","F"))))) -> B | L10: =IFERROR(IF(AND(J10>=50,I10="Present"),"PASS","Review"),"Error") -> PASS
A11: S006 | B11: Falak Singh | C11: Commerce | D11: 12-B | E11: 85 | F11: 88 | G11: 82 | H11: 87 | I11: Present | J11: =IFERROR(AVERAGE(E11:H11),0) -> 85.5 | K11: =IF(J11>=90,"A+",IF(J11>=80,"A",IF(J11>=70,"B",IF(J11>=60,"C",IF(J11>=50,"D","F"))))) -> A | L11: =IFERROR(IF(AND(J11>=50,I11="Present"),"PASS","Review"),"Error") -> PASS
A12: S007 | B12: Gaurav Tiwari | C12: Science | D12: 10-A | E12: 33 | F12: 28 | G12: 40 | H12: 35 | I12: Present | J12: =IFERROR(AVERAGE(E12:H12),0) -> 34 | K12: =IF(J12>=90,"A+",IF(J12>=80,"A",IF(J12>=70,"B",IF(J12>=60,"C",IF(J12>=50,"D","F"))))) -> F | L12: =IFERROR(IF(AND(J12>=50,I12="Present"),"PASS","Review"),"Error") -> Review
A13: S008 | B13: Hina Desai | C13: Arts | D13: 11-B | E13: 96 | F13: 94 | G13: 98 | H13: 95 | I13: Present | J13: =IFERROR(AVERAGE(E13:H13),0) -> 95.75 | K13: =IF(J13>=90,"A+",IF(J13>=80,"A",IF(J13>=70,"B",IF(J13>=60,"C",IF(J13>=50,"D","F"))))) -> A+ | L13: =IFERROR(IF(AND(J13>=50,I13="Present"),"PASS","Review"),"Error") -> PASS
A14: S009 | B14: Ishaan Kapoor | C14: Commerce | D14: 12-A | E14: 61 | F14: 65 | G14: 58 | H14: 63 | I14: Absent | J14: =IFERROR(AVERAGE(E14:H14),0) -> 61.75 | K14: =IF(J14>=90,"A+",IF(J14>=80,"A",IF(J14>=70,"B",IF(J14>=60,"C",IF(J14>=50,"D","F"))))) -> C | L14: =IFERROR(IF(AND(J14>=50,I14="Present"),"PASS","Review"),"Error") -> Review
A15: S010 | B15: Jyoti Sharma | C15: Science | D15: 10-B | E15: 77 | F15: 80 | G15: 74 | H15: 78 | I15: Present | J15: =IFERROR(AVERAGE(E15:H15),0) -> 77.25 | K15: =IF(J15>=90,"A+",IF(J15>=80,"A",IF(J15>=70,"B",IF(J15>=60,"C",IF(J15>=50,"D","F"))))) -> B | L15: =IFERROR(IF(AND(J15>=50,I15="Present"),"PASS","Review"),"Error") -> PASS
A16: S011 | B16: Kiran Mehta | C16: Arts | D16: 11-A | E16: 88 | F16: 85 | G16: 90 | H16: 86 | I16: Present | J16: =IFERROR(AVERAGE(E16:H16),0) -> 87.25 | K16: =IF(J16>=90,"A+",IF(J16>=80,"A",IF(J16>=70,"B",IF(J16>=60,"C",IF(J16>=50,"D","F"))))) -> A | L16: =IFERROR(IF(AND(J16>=50,I16="Present"),"PASS","Review"),"Error") -> PASS
A17: S012 | B17: Lavanya Nair | C17: Commerce | D17: 12-B | E17: 52 | F17: 48 | G17: 55 | H17: 50 | I17: Present | J17: =IFERROR(AVERAGE(E17:H17),0) -> 51.25 | K17: =IF(J17>=90,"A+",IF(J17>=80,"A",IF(J17>=70,"B",IF(J17>=60,"C",IF(J17>=50,"D","F"))))) -> D | L17: =IFERROR(IF(AND(J17>=50,I17="Present"),"PASS","Review"),"Error") -> PASS
... A25: S020 | B25: Tanvi Yadav | C25: Arts | D25: 11-B | E25: 100 | F25: 98 | G25: 99 | H25: 100 | I25: Present | J25: =IFERROR(AVERAGE(E25:H25),0) -> 99.25 | K25: =IF(J25>=90,"A+",IF(J25>=80,"A",IF(J25>=70,"B",IF(J25>=60,"C",IF(J25>=50,"D","F"))))) -> A+ | L25: =IFERROR(IF(AND(J25>=50,I25="Present"),"PASS","Review"),"Error") -> PASS
A27: 🏋️ PRACTICE EXERCISES — Write these formulas yourself!
A28: # | B28: Formula | C28: Task Description | D28: Answer (click to reveal) | E28: Your Answer → | F28: ✓ Correct?
A29: Exercise 1 | B29: XLOOKUP | C29: Find the Math score for Student ID 'S008' | D29: '=IFS(J6>=90,"Gold",J6>=75,"Silver",J6>=60,"Bronze",TRUE,"None") -- or use nested IF: =IF(J6>=90,"Gold",IF(J6>=75,"Silver",IF(J6>=60,"Bronze","None"))) | F29: =IFERROR(IF(E29="","⬜ Empty",IF(E29=D29,"✅ Correct!","❌ Try again")),"—") -> ⬜ Empty
A30: Exercise 2 | B30: INDEX-MATCH | C30: Find the Student Name where English score is highest | D30: =INDEX(B6:B25,MATCH(MAX(G6:G25),G6:G25,0)) -> Tanvi Yadav | F30: =IFERROR(IF(E30="","⬜ Empty",IF(E30=D30,"✅ Correct!","❌ Try again")),"—") -> ⬜ Empty
A31: Exercise 3 | B31: Nested IFS | C31: Assign scholarship: Avg≥90→Gold, Avg≥75→Silver, Avg≥60→Bronze, else None | D31: IFERROR(AVERAGE(E6:H6), 0) -- removes the = so it shows as text example | F31: =IFERROR(IF(E31="","⬜ Empty",IF(E31=D31,"✅ Correct!","❌ Try again")),"—") -> ⬜ Empty
A32: Exercise 4 | B32: SUMIFS | C32: Total Science marks for Stream='Science' AND Attendance='Present' | D32: '=SUMIFS(F6:F25,C6:C25,"Science",I6:I25,"Present") | F32: =IFERROR(IF(E32="","⬜ Empty",IF(E32=D32,"✅ Correct!","❌ Try again")),"—") -> ⬜ Empty
A33: Exercise 5 | B33: IFERROR | C33: Safe average: =IFERROR(AVERAGE(E6:H6), 0) — try it for student S004 (absent) | D33: =IFERROR(_xludf.xlookup("S099",A6:A25,B6:B25),"Student not enrolled") -> Student not enrolled | F33: =IFERROR(IF(E33="","⬜ Empty",IF(E33=D33,"✅ Correct!","❌ Try again")),"—") -> ⬜ Empty
A34: Exercise 6 | B34: Combined | C34: XLOOKUP + IFERROR: Get grade of student 'S020', show 'Unknown' if not found | D34: =IFERROR(_xludf.xlookup("S020",A6:A25,K6:K25),"Unknown") -> Unknown | F34: =IFERROR(IF(E34="","⬜ Empty",IF(E34=D34,"✅ Correct!","❌ Try again")),"—") -> ⬜ Empty
A36: 📊 SUMMARY STATS — Practice SUMIFS & COUNTIFS here
A37: Stream | B37: Total Students | C37: Present | D37: Avg Math | E37: Avg Science | F37: Top Scorer
A38: Science | B38: =COUNTIF(C$6:C$25,A38) -> 7 | C38: =COUNTIFS(C$6:C$25,A38,I$6:I$25,"Present") -> 6 | D38: =IFERROR(AVERAGEIF(C$6:C$25,A38,E$6:E$25),0) -> 63.714286 | E38: =IFERROR(AVERAGEIF(C$6:C$25,A38,F$6:F$25),0) -> 66.428571 | F38: =IFERROR(INDEX(B$6:B$25,MATCH(_xludf.maxifs(J$6:J$25,C$6:C$25,A38),J$6:J$25,0)),"N/A") -> N/A
A39: Arts | B39: =COUNTIF(C$6:C$25,A39) -> 7 | C39: =COUNTIFS(C$6:C$25,A39,I$6:I$25,"Present") -> 6 | D39: =IFERROR(AVERAGEIF(C$6:C$25,A39,E$6:E$25),0) -> 72.857143 | E39: =IFERROR(AVERAGEIF(C$6:C$25,A39,F$6:F$25),0) -> 71.142857 | F39: =IFERROR(INDEX(B$6:B$25,MATCH(_xludf.maxifs(J$6:J$25,C$6:C$25,A39),J$6:J$25,0)),"N/A") -> N/A
A40: Commerce | B40: =COUNTIF(C$6:C$25,A40) -> 6 | C40: =COUNTIFS(C$6:C$25,A40,I$6:I$25,"Present") -> 4 | D40: =IFERROR(AVERAGEIF(C$6:C$25,A40,E$6:E$25),0) -> 78 | E40: =IFERROR(AVERAGEIF(C$6:C$25,A40,F$6:F$25),0) -> 78.333333 | F40: =IFERROR(INDEX(B$6:B$25,MATCH(_xludf.maxifs(J$6:J$25,C$6:C$25,A40),J$6:J$25,0)),"N/A") -> N/A

Sheet 📋 Cheat Sheet
A1: 📋 FORMULA CHEAT SHEET — Quick Reference
A3: Formula | B3: Full Syntax | C3: Purpose | D3: Example
A4: XLOOKUP | B4: '=xlookup(lookup_val, lookup_array, return_array, [if_not_found], [match_mode], [search_mode]) | C4: Modern lookup — works left/right, no column number needed | D4: '=xlookup("E001",A:A,B:B,"Not Found")
A5: INDEX | B5: '=INDEX(array, row_num, [col_num]) | C5: Returns the value at a given position in a range | D5: '=INDEX(B6:B30, 5) → returns value in row 5
A6: MATCH | B6: '=MATCH(lookup_val, lookup_array, [match_type]) | C6: Returns the position number of a value in a range (use 0 for exact match) | D6: '=MATCH("Ravi",B6:B30,0) → returns row number
A7: INDEX+MATCH | B7: '=INDEX(return_col, MATCH(lookup_val, search_col, 0)) | C7: Power combo: find position with MATCH, get value with INDEX | D7: '=INDEX(F6:F30, MATCH("E005",A6:A30,0))
A8: IF | B8: '=IF(condition, value_if_true, value_if_false) | C8: Single conditional check | D8: '=IF(G6>100000,"High","Low")
A9: Nested IF | B9: '=IF(C1,V1, IF(C2,V2, IF(C3,V3, default))) | C9: Multiple conditions chained — max 3 levels recommended | D9: '=IF(G6>150000,"Exceptional",IF(G6>100000,"High","Low"))
A10: IFS | B10: '=ifs(cond1,VAL1, cond2,VAL2, ..., TRUE(), default) | C10: Cleaner alternative to Nested IF for 3+ conditions | D10: '=ifs(J6>=90,"A+",J6>=80,"A",TRUE(),"B")
A11: SUMIFS | B11: '=SUMIFS(sum_range, crit_range1, crit1, crit_range2, crit2, ...) | C11: Sum values that meet MULTIPLE conditions (sum_range is FIRST!) | D11: '=SUMIFS(G6:G30,C6:C30,"Sales",D6:D30,"North")
A12: COUNTIFS | B12: '=COUNTIFS(crit_range1, crit1, crit_range2, crit2, ...) | C12: Count rows meeting multiple conditions | D12: '=COUNTIFS(C6:C30,"Sales",J6:J30,"Active")
A13: AVERAGEIFS | B13: '=AVERAGEIFS(avg_range, crit_range1, crit1, ...) | C13: Average of values meeting multiple conditions | D13: '=AVERAGEIFS(F6:F30,C6:C30,"Sales",E6:E30,"Senior")
A14: IFERROR | B14: '=IFERROR(formula, value_if_error) | C14: Catches ALL errors and returns a clean fallback value | D14: '=IFERROR(A1/B1, 0)
A15: IFNA | B15: '=ifna(formula, value_if_na) | C15: Only catches N/A errors from failed lookups. Other errors still display normally. | D15: '=ifna(VLOOKUP(A1,table,2,0),"Not Found")
